## Exception과 Error의 차이는?

![image](https://user-images.githubusercontent.com/38120537/157680618-7beb73b7-3aa4-4af4-be19-9617e9463159.png)


### 예외의 종류
- checked exception
- error
- runtimeException 혹은 unchecked exception

### Error
- 컴퓨터 하드웨어의 오동작 또는 고장으로 인해 응용 프로그램에 이상이 생겼거나 JVM 실행에 문제가 생겼을 경우 발생하는 것이다.
- 프로세스에 영향을 준다.
- 시스템 레벨에서 발생한다.(자바 프로그램 외의 오류)

#### 종류
- VirtualMachineError
- OutOfMemoryError
- StackOverFlowError  
등등

### Exception
- 컴퓨터의 에러가 아닌 사용자의 잘못된 조작 또는 개발자의 잘못된 코딩으로 인해 발생하는 프로그램 오류이다.
- 예외가 발생하면 프로그램이 종료가 된다는 것은 에러와 동일하지만 예외는 예외처리를 통해 프로그램이 종료되지 않고 정상적으로 작동되게 만들어줄 수 있다.
- 개발자가 구현한 로직에서 발생
- 쓰레드에 영향을 준다.

#### 종류

#### Checked Exception

**특징**
- 반드시 예외 처리해야한다.
- 컴파일 단계에서 발생한다.


**대표 예외**
- RuntimeException를 제외한 모든 예외
- IOException

#### Runtime Exception
- 예외가 발생할 것을 미리 감지하지 못했을 때 발생.
- 런타임 예외에 해당은 모든 예외들은 RuntimeException을 확장한 예외들이다.


### 모든 예외의 부모 클래스는 java.lang.Throwable 클래스이다.
- Exception과 Error 클래스는 Throwable 클래스를 상속받았다.
- Exception이나 Error를 처리할 때 Trowable로 처리해도 무관하다.

## 자바에서 예외 처리 방법(try, catch, throw, throws, finally)

### 예외처리란?
예외처리란 프로그램이 실행 시 발생할 수 있는 예기치 못한 예외의 발생에 대비한 코드를 작성하는 것이다.  
OutOfMemoryError와 같이 프로그래머, 혹은 사용자의 실수가 아닌 에러는 어쩔 수 없지만, 예외는 프로그래머가 미리 처리를 해두어야한다.  

이때 처리하지 못한 예외는 비정상적으로 종료시키며, JVM의 예외처리기가 받아서 예외의 원인을 화면에 출력한다.

### try-catch

```java
try {
    System.out.println(5/0);
} catch (Exception e) {
    System.out.println(e);
    System.out.println("0으로 나눌 수 없다.");
}

// 결과
java.lang.ArithmeticException: / by zero
0으로 나눌 수 없다.
```

0으로 나눗셈을 하려고하면 ArithmeticException이 발생한다. 예외가 발생하고 catch문안의 예외 처리 코드를 실행한다. try 문에 예외가 아닌 정상적인 코드를
삽입하면, catch문은 실행되지 않는다.

### 어떻게 동작하는가?
try 블럭이 예외가 발생하는 문장이 포함되어있다면, 이 예외를 처리할 catch 블럭이 있는지를 먼저 찾는다.  
catch 블럭의 예외와, 실제 발생한 예외를 instanceof 연산자를 사용해 검사를한다.  
검사 결과 true라면 catch문을 수행하고, false라면 예외는 처리되지 않는다.  

이때 catch 블럭의 괄호안에는 원하는 예외를 작성할 수 있으며, 하나의 try 블럭에 여러개의 catch 블럭을 작성할 수 있다.

```java
try {
    System.out.println(5/0);
} catch (NullPointerException e1) {
    System.out.println("e1: " + e1);
} catch (ArithmeticException e2) {
    System.out.println("e2: " + e2);
} catch (Exception e3) {
    System.out.println("e3: " + e3);
}

// 결과
e2: java.lang.ArithmeticException: / by zero
```
지금은 NullPointerException이 아니라 ArithmeticException이기 때문에 두번째 catch문을 수행할 것이다.  
세번째 catch문인 Exception도 처리할 수 있지만, 이미 처리가 완료된 상황이기 때문에 세번째 catch 블럭은 검사하지 않는다.

### printStackTrace(), getMessage()
예외처리를 할 때 발생한 예외의 대한 정보가 담긴 메서드이다. catch 블럭의 참조변수를 통해 인스턴스에 접근할 수 있다.
- printStackTrace()
  - 예외 발생 당시에 호출스택에 있었던 메서드의 정보와 예외 메시지를 화면에 출력한다.
- getMessage()
  - 발생한 예외 클래스의 인스턴스에 저장된 메시지를 얻을 수 있다. 


### 멀티 catch
JDK 1.7부터 추가된 기능이다. '|' 기호를 사용해 여러 catch 블럭을 하나로 합칠 수 있는데, 이것을 멀티 catch라고 한다.  
그러나 연결되어 있는 예외 클래스가 부모 자식 관계에 있다면, 컴파일 에러가 발생한다.

```java
try {

} catch (NullPointerException | ArithmeticException e1) {

} catch (IllegalArgumentException | Exception e2) { // 컴파일 에러

}
```

### finally
finally 블럭은 예외와 상관없이 실행되는 블럭이다. 만약 try 블럭에서 예외가 발생하면 catch 블럭을 찾기 때문에 꼭 필요한 코드가 실행되지 않을 수 있다.  

기본적으로 try-catch-finally 의 구조를 가진다.

```java
try {
    System.out.println(5/0);
    System.out.println("----------");
} catch (ArithmeticException e) {
    System.out.println(e);
} finally {
    System.out.println("무조건 실행!");
}

// 결과
java.lang.ArithmeticException: / by zero
무조건 실행!
```

### throw
throw 키워드를 사용하면 프로그래머 고의적으로 예외를 발생시킬 수 있다.

```java
public class Test {
    public static void main(String[] args) {
        Test test = new Test();
        test.throwMethod();
    }

    void throwMethod() {
        String s = null;

        if(s == null) {
            throw new NullPointerException();
        } else {
            System.out.println(s);
        }
    }
}
```

### throws
throws는 예외를 던지는(위임하는) 역할을 한다.

```java
public class Test {
    public static void main(String[] args) throws Exception {
        Test test = new Test();
        test.parseInt("123T");
    }

    public Integer parseInt(String str) throws Exception {
        return Integer.parseInt(str);
    }
}
```

## 커스텀한 예외 만드는 방법
예외를 커스텀하기 위해선 Exception을 상속받아야한다. 그후 생성자를 만들어 출력할 메시지를 받아 출력할 수 있다.  
이때 기본 생성자를 만들어 사용하면 메시지 없이 어떤 예외인지만 볼 수 있다.

```java
public class AgeException extends Exception{

    public AgeException() {
    }

    public AgeException(String message) {
        super(message);
    }
}
```

```java
public class Service {

    public void setAge(int age) throws AgeException {
        if (age < 0) {
            throw new AgeException("음수 불가능");
        }

        System.out.println("완료");
    }
}
```

```java
public class Test {
    public static void main(String[] args) throws Exception {
        Service service = new Service();

        service.setAge(-1);
    }
}
```

<img width="648" alt="스크린샷 2022-03-10 오후 11 38 10" src="https://user-images.githubusercontent.com/38120537/157684680-ad3cf55d-f5b5-4f54-8b4b-b409868a4c5e.png">

